mysqldump --single-transaction --quick --lock-tables=false -u _d7b2a4261c302107 -pC541lZ1J9x11RpHI _d7b2a4261c302107 -h 127.0.0.1 -P 3306   | /usr/bin/gzip >> ./projectmanagement.sys/private/backups/20211022_120002-projectmanagement_sys-database.sql.gz

Backup Summary for projectmanagement.sys at 2021-10-22 12:00:02.977691
Config  : ./projectmanagement.sys/private/backups/20211022_120002-projectmanagement_sys-site_config_backup.json 94.0B
Database: ./projectmanagement.sys/private/backups/20211022_120002-projectmanagement_sys-database.sql.gz         243.9KiB
Backup for Site projectmanagement.sys has been successfully completed
Backup failed for Site projectmanagement.system. Database or site_config.json may be corrupted
Traceback (most recent call last):
  File "/home/user/assignment/apps/frappe/frappe/commands/site.py", line 429, in backup
    odb = scheduled_backup(
  File "/home/user/assignment/apps/frappe/frappe/utils/backups.py", line 515, in scheduled_backup
    odb = new_backup(
  File "/home/user/assignment/apps/frappe/frappe/utils/backups.py", line 549, in new_backup
    odb = BackupGenerator(
  File "/home/user/assignment/apps/frappe/frappe/utils/backups.py", line 85, in __init__
    self.setup_backup_tables()
  File "/home/user/assignment/apps/frappe/frappe/utils/backups.py", line 119, in setup_backup_tables
    existing_doctypes = set([x.name for x in frappe.get_all("DocType")])
  File "/home/user/assignment/apps/frappe/frappe/__init__.py", line 1460, in get_all
    return get_list(doctype, *args, **kwargs)
  File "/home/user/assignment/apps/frappe/frappe/__init__.py", line 1433, in get_list
    return frappe.model.db_query.DatabaseQuery(doctype).execute(*args, **kwargs)
  File "/home/user/assignment/apps/frappe/frappe/model/db_query.py", line 102, in execute
    self.columns = self.get_table_columns()
  File "/home/user/assignment/apps/frappe/frappe/model/db_query.py", line 339, in get_table_columns
    return get_table_columns(self.doctype)
  File "/home/user/assignment/apps/frappe/frappe/model/meta.py", line 49, in get_table_columns
    return frappe.db.get_table_columns(doctype)
  File "/home/user/assignment/apps/frappe/frappe/database/database.py", line 893, in get_table_columns
    columns = self.get_db_table_columns('tab' + doctype)
  File "/home/user/assignment/apps/frappe/frappe/database/database.py", line 881, in get_db_table_columns
    columns = [r[0] for r in self.sql('''
  File "/home/user/assignment/apps/frappe/frappe/database/database.py", line 122, in sql
    self.connect()
  File "/home/user/assignment/apps/frappe/frappe/database/database.py", line 74, in connect
    self._conn = self.get_connection()
  File "/home/user/assignment/apps/frappe/frappe/database/mariadb/database.py", line 73, in get_connection
    conn = pymysql.connect(
  File "/home/user/assignment/env/lib/python3.8/site-packages/pymysql/connections.py", line 353, in __init__
    self.connect()
  File "/home/user/assignment/env/lib/python3.8/site-packages/pymysql/connections.py", line 633, in connect
    self._request_authentication()
  File "/home/user/assignment/env/lib/python3.8/site-packages/pymysql/connections.py", line 907, in _request_authentication
    auth_packet = self._read_packet()
  File "/home/user/assignment/env/lib/python3.8/site-packages/pymysql/connections.py", line 725, in _read_packet
    packet.raise_for_error()
  File "/home/user/assignment/env/lib/python3.8/site-packages/pymysql/protocol.py", line 221, in raise_for_error
    err.raise_mysql_exception(self._data)
  File "/home/user/assignment/env/lib/python3.8/site-packages/pymysql/err.py", line 143, in raise_mysql_exception
    raise errorclass(errno, errval)
pymysql.err.OperationalError: (1045, "Access denied for user '_72158affdf1791ca'@'localhost' (using password: YES)")

mysqldump --single-transaction --quick --lock-tables=false -u _d7b2a4261c302107 -pC541lZ1J9x11RpHI _d7b2a4261c302107 -h 127.0.0.1 -P 3306   | /usr/bin/gzip >> ./projectmanagement.sys/private/backups/20211022_180002-projectmanagement_sys-database.sql.gz

Backup Summary for projectmanagement.sys at 2021-10-22 18:00:04.347815
Config  : ./projectmanagement.sys/private/backups/20211022_180002-projectmanagement_sys-site_config_backup.json 115.0B
Database: ./projectmanagement.sys/private/backups/20211022_180002-projectmanagement_sys-database.sql.gz         303.2KiB
Backup for Site projectmanagement.sys has been successfully completed
Backup failed for Site projectmanagement.system. Database or site_config.json may be corrupted
Traceback (most recent call last):
  File "/home/user/assignment/apps/frappe/frappe/commands/site.py", line 429, in backup
    odb = scheduled_backup(
  File "/home/user/assignment/apps/frappe/frappe/utils/backups.py", line 515, in scheduled_backup
    odb = new_backup(
  File "/home/user/assignment/apps/frappe/frappe/utils/backups.py", line 549, in new_backup
    odb = BackupGenerator(
  File "/home/user/assignment/apps/frappe/frappe/utils/backups.py", line 85, in __init__
    self.setup_backup_tables()
  File "/home/user/assignment/apps/frappe/frappe/utils/backups.py", line 119, in setup_backup_tables
    existing_doctypes = set([x.name for x in frappe.get_all("DocType")])
  File "/home/user/assignment/apps/frappe/frappe/__init__.py", line 1460, in get_all
    return get_list(doctype, *args, **kwargs)
  File "/home/user/assignment/apps/frappe/frappe/__init__.py", line 1433, in get_list
    return frappe.model.db_query.DatabaseQuery(doctype).execute(*args, **kwargs)
  File "/home/user/assignment/apps/frappe/frappe/model/db_query.py", line 102, in execute
    self.columns = self.get_table_columns()
  File "/home/user/assignment/apps/frappe/frappe/model/db_query.py", line 339, in get_table_columns
    return get_table_columns(self.doctype)
  File "/home/user/assignment/apps/frappe/frappe/model/meta.py", line 49, in get_table_columns
    return frappe.db.get_table_columns(doctype)
  File "/home/user/assignment/apps/frappe/frappe/database/database.py", line 893, in get_table_columns
    columns = self.get_db_table_columns('tab' + doctype)
  File "/home/user/assignment/apps/frappe/frappe/database/database.py", line 881, in get_db_table_columns
    columns = [r[0] for r in self.sql('''
  File "/home/user/assignment/apps/frappe/frappe/database/database.py", line 122, in sql
    self.connect()
  File "/home/user/assignment/apps/frappe/frappe/database/database.py", line 74, in connect
    self._conn = self.get_connection()
  File "/home/user/assignment/apps/frappe/frappe/database/mariadb/database.py", line 73, in get_connection
    conn = pymysql.connect(
  File "/home/user/assignment/env/lib/python3.8/site-packages/pymysql/connections.py", line 353, in __init__
    self.connect()
  File "/home/user/assignment/env/lib/python3.8/site-packages/pymysql/connections.py", line 633, in connect
    self._request_authentication()
  File "/home/user/assignment/env/lib/python3.8/site-packages/pymysql/connections.py", line 907, in _request_authentication
    auth_packet = self._read_packet()
  File "/home/user/assignment/env/lib/python3.8/site-packages/pymysql/connections.py", line 725, in _read_packet
    packet.raise_for_error()
  File "/home/user/assignment/env/lib/python3.8/site-packages/pymysql/protocol.py", line 221, in raise_for_error
    err.raise_mysql_exception(self._data)
  File "/home/user/assignment/env/lib/python3.8/site-packages/pymysql/err.py", line 143, in raise_mysql_exception
    raise errorclass(errno, errval)
pymysql.err.OperationalError: (1045, "Access denied for user '_72158affdf1791ca'@'localhost' (using password: YES)")

mysqldump --single-transaction --quick --lock-tables=false -u _d7b2a4261c302107 -pC541lZ1J9x11RpHI _d7b2a4261c302107 -h 127.0.0.1 -P 3306   | /usr/bin/gzip >> ./projectmanagement.sys/private/backups/20211023_180002-projectmanagement_sys-database.sql.gz

Backup Summary for projectmanagement.sys at 2021-10-23 18:00:03.444624
Config  : ./projectmanagement.sys/private/backups/20211023_180002-projectmanagement_sys-site_config_backup.json 115.0B
Database: ./projectmanagement.sys/private/backups/20211023_180002-projectmanagement_sys-database.sql.gz         332.8KiB
Backup for Site projectmanagement.sys has been successfully completed
Backup failed for Site projectmanagement.system. Database or site_config.json may be corrupted
Traceback (most recent call last):
  File "/home/user/assignment/apps/frappe/frappe/commands/site.py", line 429, in backup
    odb = scheduled_backup(
  File "/home/user/assignment/apps/frappe/frappe/utils/backups.py", line 515, in scheduled_backup
    odb = new_backup(
  File "/home/user/assignment/apps/frappe/frappe/utils/backups.py", line 549, in new_backup
    odb = BackupGenerator(
  File "/home/user/assignment/apps/frappe/frappe/utils/backups.py", line 85, in __init__
    self.setup_backup_tables()
  File "/home/user/assignment/apps/frappe/frappe/utils/backups.py", line 119, in setup_backup_tables
    existing_doctypes = set([x.name for x in frappe.get_all("DocType")])
  File "/home/user/assignment/apps/frappe/frappe/__init__.py", line 1460, in get_all
    return get_list(doctype, *args, **kwargs)
  File "/home/user/assignment/apps/frappe/frappe/__init__.py", line 1433, in get_list
    return frappe.model.db_query.DatabaseQuery(doctype).execute(*args, **kwargs)
  File "/home/user/assignment/apps/frappe/frappe/model/db_query.py", line 102, in execute
    self.columns = self.get_table_columns()
  File "/home/user/assignment/apps/frappe/frappe/model/db_query.py", line 339, in get_table_columns
    return get_table_columns(self.doctype)
  File "/home/user/assignment/apps/frappe/frappe/model/meta.py", line 49, in get_table_columns
    return frappe.db.get_table_columns(doctype)
  File "/home/user/assignment/apps/frappe/frappe/database/database.py", line 893, in get_table_columns
    columns = self.get_db_table_columns('tab' + doctype)
  File "/home/user/assignment/apps/frappe/frappe/database/database.py", line 881, in get_db_table_columns
    columns = [r[0] for r in self.sql('''
  File "/home/user/assignment/apps/frappe/frappe/database/database.py", line 122, in sql
    self.connect()
  File "/home/user/assignment/apps/frappe/frappe/database/database.py", line 74, in connect
    self._conn = self.get_connection()
  File "/home/user/assignment/apps/frappe/frappe/database/mariadb/database.py", line 73, in get_connection
    conn = pymysql.connect(
  File "/home/user/assignment/env/lib/python3.8/site-packages/pymysql/connections.py", line 353, in __init__
    self.connect()
  File "/home/user/assignment/env/lib/python3.8/site-packages/pymysql/connections.py", line 633, in connect
    self._request_authentication()
  File "/home/user/assignment/env/lib/python3.8/site-packages/pymysql/connections.py", line 907, in _request_authentication
    auth_packet = self._read_packet()
  File "/home/user/assignment/env/lib/python3.8/site-packages/pymysql/connections.py", line 725, in _read_packet
    packet.raise_for_error()
  File "/home/user/assignment/env/lib/python3.8/site-packages/pymysql/protocol.py", line 221, in raise_for_error
    err.raise_mysql_exception(self._data)
  File "/home/user/assignment/env/lib/python3.8/site-packages/pymysql/err.py", line 143, in raise_mysql_exception
    raise errorclass(errno, errval)
pymysql.err.OperationalError: (1045, "Access denied for user '_72158affdf1791ca'@'localhost' (using password: YES)")

mysqldump --single-transaction --quick --lock-tables=false -u _d7b2a4261c302107 -pC541lZ1J9x11RpHI _d7b2a4261c302107 -h 127.0.0.1 -P 3306   | /usr/bin/gzip >> ./projectmanagement.sys/private/backups/20211025_120001-projectmanagement_sys-database.sql.gz

Backup Summary for projectmanagement.sys at 2021-10-25 12:00:02.784241
Config  : ./projectmanagement.sys/private/backups/20211025_120001-projectmanagement_sys-site_config_backup.json 115.0B
Database: ./projectmanagement.sys/private/backups/20211025_120001-projectmanagement_sys-database.sql.gz         385.8KiB
Backup for Site projectmanagement.sys has been successfully completed
Backup failed for Site projectmanagement.system. Database or site_config.json may be corrupted
Traceback (most recent call last):
  File "/home/user/assignment/apps/frappe/frappe/commands/site.py", line 429, in backup
    odb = scheduled_backup(
  File "/home/user/assignment/apps/frappe/frappe/utils/backups.py", line 515, in scheduled_backup
    odb = new_backup(
  File "/home/user/assignment/apps/frappe/frappe/utils/backups.py", line 549, in new_backup
    odb = BackupGenerator(
  File "/home/user/assignment/apps/frappe/frappe/utils/backups.py", line 85, in __init__
    self.setup_backup_tables()
  File "/home/user/assignment/apps/frappe/frappe/utils/backups.py", line 119, in setup_backup_tables
    existing_doctypes = set([x.name for x in frappe.get_all("DocType")])
  File "/home/user/assignment/apps/frappe/frappe/__init__.py", line 1460, in get_all
    return get_list(doctype, *args, **kwargs)
  File "/home/user/assignment/apps/frappe/frappe/__init__.py", line 1433, in get_list
    return frappe.model.db_query.DatabaseQuery(doctype).execute(*args, **kwargs)
  File "/home/user/assignment/apps/frappe/frappe/model/db_query.py", line 102, in execute
    self.columns = self.get_table_columns()
  File "/home/user/assignment/apps/frappe/frappe/model/db_query.py", line 339, in get_table_columns
    return get_table_columns(self.doctype)
  File "/home/user/assignment/apps/frappe/frappe/model/meta.py", line 49, in get_table_columns
    return frappe.db.get_table_columns(doctype)
  File "/home/user/assignment/apps/frappe/frappe/database/database.py", line 893, in get_table_columns
    columns = self.get_db_table_columns('tab' + doctype)
  File "/home/user/assignment/apps/frappe/frappe/database/database.py", line 881, in get_db_table_columns
    columns = [r[0] for r in self.sql('''
  File "/home/user/assignment/apps/frappe/frappe/database/database.py", line 122, in sql
    self.connect()
  File "/home/user/assignment/apps/frappe/frappe/database/database.py", line 74, in connect
    self._conn = self.get_connection()
  File "/home/user/assignment/apps/frappe/frappe/database/mariadb/database.py", line 73, in get_connection
    conn = pymysql.connect(
  File "/home/user/assignment/env/lib/python3.8/site-packages/pymysql/connections.py", line 353, in __init__
    self.connect()
  File "/home/user/assignment/env/lib/python3.8/site-packages/pymysql/connections.py", line 633, in connect
    self._request_authentication()
  File "/home/user/assignment/env/lib/python3.8/site-packages/pymysql/connections.py", line 907, in _request_authentication
    auth_packet = self._read_packet()
  File "/home/user/assignment/env/lib/python3.8/site-packages/pymysql/connections.py", line 725, in _read_packet
    packet.raise_for_error()
  File "/home/user/assignment/env/lib/python3.8/site-packages/pymysql/protocol.py", line 221, in raise_for_error
    err.raise_mysql_exception(self._data)
  File "/home/user/assignment/env/lib/python3.8/site-packages/pymysql/err.py", line 143, in raise_mysql_exception
    raise errorclass(errno, errval)
pymysql.err.OperationalError: (1045, "Access denied for user '_72158affdf1791ca'@'localhost' (using password: YES)")

mysqldump --single-transaction --quick --lock-tables=false -u _d7b2a4261c302107 -pC541lZ1J9x11RpHI _d7b2a4261c302107 -h 127.0.0.1 -P 3306   | /usr/bin/gzip >> ./projectmanagement.sys/private/backups/20211025_180002-projectmanagement_sys-database.sql.gz

Backup Summary for projectmanagement.sys at 2021-10-25 18:00:03.568641
Config  : ./projectmanagement.sys/private/backups/20211025_180002-projectmanagement_sys-site_config_backup.json 183.0B
Database: ./projectmanagement.sys/private/backups/20211025_180002-projectmanagement_sys-database.sql.gz         443.6KiB
Backup for Site projectmanagement.sys has been successfully completed
Backup failed for Site projectmanagement.system. Database or site_config.json may be corrupted
Traceback (most recent call last):
  File "/home/user/assignment/apps/frappe/frappe/commands/site.py", line 429, in backup
    odb = scheduled_backup(
  File "/home/user/assignment/apps/frappe/frappe/utils/backups.py", line 515, in scheduled_backup
    odb = new_backup(
  File "/home/user/assignment/apps/frappe/frappe/utils/backups.py", line 549, in new_backup
    odb = BackupGenerator(
  File "/home/user/assignment/apps/frappe/frappe/utils/backups.py", line 85, in __init__
    self.setup_backup_tables()
  File "/home/user/assignment/apps/frappe/frappe/utils/backups.py", line 119, in setup_backup_tables
    existing_doctypes = set([x.name for x in frappe.get_all("DocType")])
  File "/home/user/assignment/apps/frappe/frappe/__init__.py", line 1460, in get_all
    return get_list(doctype, *args, **kwargs)
  File "/home/user/assignment/apps/frappe/frappe/__init__.py", line 1433, in get_list
    return frappe.model.db_query.DatabaseQuery(doctype).execute(*args, **kwargs)
  File "/home/user/assignment/apps/frappe/frappe/model/db_query.py", line 102, in execute
    self.columns = self.get_table_columns()
  File "/home/user/assignment/apps/frappe/frappe/model/db_query.py", line 339, in get_table_columns
    return get_table_columns(self.doctype)
  File "/home/user/assignment/apps/frappe/frappe/model/meta.py", line 49, in get_table_columns
    return frappe.db.get_table_columns(doctype)
  File "/home/user/assignment/apps/frappe/frappe/database/database.py", line 893, in get_table_columns
    columns = self.get_db_table_columns('tab' + doctype)
  File "/home/user/assignment/apps/frappe/frappe/database/database.py", line 881, in get_db_table_columns
    columns = [r[0] for r in self.sql('''
  File "/home/user/assignment/apps/frappe/frappe/database/database.py", line 122, in sql
    self.connect()
  File "/home/user/assignment/apps/frappe/frappe/database/database.py", line 74, in connect
    self._conn = self.get_connection()
  File "/home/user/assignment/apps/frappe/frappe/database/mariadb/database.py", line 73, in get_connection
    conn = pymysql.connect(
  File "/home/user/assignment/env/lib/python3.8/site-packages/pymysql/connections.py", line 353, in __init__
    self.connect()
  File "/home/user/assignment/env/lib/python3.8/site-packages/pymysql/connections.py", line 633, in connect
    self._request_authentication()
  File "/home/user/assignment/env/lib/python3.8/site-packages/pymysql/connections.py", line 907, in _request_authentication
    auth_packet = self._read_packet()
  File "/home/user/assignment/env/lib/python3.8/site-packages/pymysql/connections.py", line 725, in _read_packet
    packet.raise_for_error()
  File "/home/user/assignment/env/lib/python3.8/site-packages/pymysql/protocol.py", line 221, in raise_for_error
    err.raise_mysql_exception(self._data)
  File "/home/user/assignment/env/lib/python3.8/site-packages/pymysql/err.py", line 143, in raise_mysql_exception
    raise errorclass(errno, errval)
pymysql.err.OperationalError: (1045, "Access denied for user '_72158affdf1791ca'@'localhost' (using password: YES)")

mysqldump --single-transaction --quick --lock-tables=false -u _d7b2a4261c302107 -pC541lZ1J9x11RpHI _d7b2a4261c302107 -h 127.0.0.1 -P 3306   | /usr/bin/gzip >> ./projectmanagement.sys/private/backups/20211026_000002-projectmanagement_sys-database.sql.gz

Backup Summary for projectmanagement.sys at 2021-10-26 00:00:04.316439
Config  : ./projectmanagement.sys/private/backups/20211026_000002-projectmanagement_sys-site_config_backup.json 183.0B
Database: ./projectmanagement.sys/private/backups/20211026_000002-projectmanagement_sys-database.sql.gz         463.9KiB
Backup for Site projectmanagement.sys has been successfully completed
Backup failed for Site projectmanagement.system. Database or site_config.json may be corrupted
Traceback (most recent call last):
  File "/home/user/assignment/apps/frappe/frappe/commands/site.py", line 429, in backup
    odb = scheduled_backup(
  File "/home/user/assignment/apps/frappe/frappe/utils/backups.py", line 515, in scheduled_backup
    odb = new_backup(
  File "/home/user/assignment/apps/frappe/frappe/utils/backups.py", line 549, in new_backup
    odb = BackupGenerator(
  File "/home/user/assignment/apps/frappe/frappe/utils/backups.py", line 85, in __init__
    self.setup_backup_tables()
  File "/home/user/assignment/apps/frappe/frappe/utils/backups.py", line 119, in setup_backup_tables
    existing_doctypes = set([x.name for x in frappe.get_all("DocType")])
  File "/home/user/assignment/apps/frappe/frappe/__init__.py", line 1460, in get_all
    return get_list(doctype, *args, **kwargs)
  File "/home/user/assignment/apps/frappe/frappe/__init__.py", line 1433, in get_list
    return frappe.model.db_query.DatabaseQuery(doctype).execute(*args, **kwargs)
  File "/home/user/assignment/apps/frappe/frappe/model/db_query.py", line 102, in execute
    self.columns = self.get_table_columns()
  File "/home/user/assignment/apps/frappe/frappe/model/db_query.py", line 339, in get_table_columns
    return get_table_columns(self.doctype)
  File "/home/user/assignment/apps/frappe/frappe/model/meta.py", line 49, in get_table_columns
    return frappe.db.get_table_columns(doctype)
  File "/home/user/assignment/apps/frappe/frappe/database/database.py", line 893, in get_table_columns
    columns = self.get_db_table_columns('tab' + doctype)
  File "/home/user/assignment/apps/frappe/frappe/database/database.py", line 881, in get_db_table_columns
    columns = [r[0] for r in self.sql('''
  File "/home/user/assignment/apps/frappe/frappe/database/database.py", line 122, in sql
    self.connect()
  File "/home/user/assignment/apps/frappe/frappe/database/database.py", line 74, in connect
    self._conn = self.get_connection()
  File "/home/user/assignment/apps/frappe/frappe/database/mariadb/database.py", line 73, in get_connection
    conn = pymysql.connect(
  File "/home/user/assignment/env/lib/python3.8/site-packages/pymysql/connections.py", line 353, in __init__
    self.connect()
  File "/home/user/assignment/env/lib/python3.8/site-packages/pymysql/connections.py", line 633, in connect
    self._request_authentication()
  File "/home/user/assignment/env/lib/python3.8/site-packages/pymysql/connections.py", line 907, in _request_authentication
    auth_packet = self._read_packet()
  File "/home/user/assignment/env/lib/python3.8/site-packages/pymysql/connections.py", line 725, in _read_packet
    packet.raise_for_error()
  File "/home/user/assignment/env/lib/python3.8/site-packages/pymysql/protocol.py", line 221, in raise_for_error
    err.raise_mysql_exception(self._data)
  File "/home/user/assignment/env/lib/python3.8/site-packages/pymysql/err.py", line 143, in raise_mysql_exception
    raise errorclass(errno, errval)
pymysql.err.OperationalError: (1045, "Access denied for user '_72158affdf1791ca'@'localhost' (using password: YES)")

mysqldump --single-transaction --quick --lock-tables=false -u _d7b2a4261c302107 -pC541lZ1J9x11RpHI _d7b2a4261c302107 -h 127.0.0.1 -P 3306   | /usr/bin/gzip >> ./projectmanagement.sys/private/backups/20211026_120002-projectmanagement_sys-database.sql.gz

Backup Summary for projectmanagement.sys at 2021-10-26 12:00:03.945084
Config  : ./projectmanagement.sys/private/backups/20211026_120002-projectmanagement_sys-site_config_backup.json 183.0B
Database: ./projectmanagement.sys/private/backups/20211026_120002-projectmanagement_sys-database.sql.gz         526.0KiB
Backup for Site projectmanagement.sys has been successfully completed
Backup failed for Site projectmanagement.system. Database or site_config.json may be corrupted
Traceback (most recent call last):
  File "/home/user/assignment/apps/frappe/frappe/commands/site.py", line 429, in backup
    odb = scheduled_backup(
  File "/home/user/assignment/apps/frappe/frappe/utils/backups.py", line 515, in scheduled_backup
    odb = new_backup(
  File "/home/user/assignment/apps/frappe/frappe/utils/backups.py", line 549, in new_backup
    odb = BackupGenerator(
  File "/home/user/assignment/apps/frappe/frappe/utils/backups.py", line 85, in __init__
    self.setup_backup_tables()
  File "/home/user/assignment/apps/frappe/frappe/utils/backups.py", line 119, in setup_backup_tables
    existing_doctypes = set([x.name for x in frappe.get_all("DocType")])
  File "/home/user/assignment/apps/frappe/frappe/__init__.py", line 1460, in get_all
    return get_list(doctype, *args, **kwargs)
  File "/home/user/assignment/apps/frappe/frappe/__init__.py", line 1433, in get_list
    return frappe.model.db_query.DatabaseQuery(doctype).execute(*args, **kwargs)
  File "/home/user/assignment/apps/frappe/frappe/model/db_query.py", line 102, in execute
    self.columns = self.get_table_columns()
  File "/home/user/assignment/apps/frappe/frappe/model/db_query.py", line 339, in get_table_columns
    return get_table_columns(self.doctype)
  File "/home/user/assignment/apps/frappe/frappe/model/meta.py", line 49, in get_table_columns
    return frappe.db.get_table_columns(doctype)
  File "/home/user/assignment/apps/frappe/frappe/database/database.py", line 893, in get_table_columns
    columns = self.get_db_table_columns('tab' + doctype)
  File "/home/user/assignment/apps/frappe/frappe/database/database.py", line 881, in get_db_table_columns
    columns = [r[0] for r in self.sql('''
  File "/home/user/assignment/apps/frappe/frappe/database/database.py", line 122, in sql
    self.connect()
  File "/home/user/assignment/apps/frappe/frappe/database/database.py", line 74, in connect
    self._conn = self.get_connection()
  File "/home/user/assignment/apps/frappe/frappe/database/mariadb/database.py", line 73, in get_connection
    conn = pymysql.connect(
  File "/home/user/assignment/env/lib/python3.8/site-packages/pymysql/connections.py", line 353, in __init__
    self.connect()
  File "/home/user/assignment/env/lib/python3.8/site-packages/pymysql/connections.py", line 633, in connect
    self._request_authentication()
  File "/home/user/assignment/env/lib/python3.8/site-packages/pymysql/connections.py", line 907, in _request_authentication
    auth_packet = self._read_packet()
  File "/home/user/assignment/env/lib/python3.8/site-packages/pymysql/connections.py", line 725, in _read_packet
    packet.raise_for_error()
  File "/home/user/assignment/env/lib/python3.8/site-packages/pymysql/protocol.py", line 221, in raise_for_error
    err.raise_mysql_exception(self._data)
  File "/home/user/assignment/env/lib/python3.8/site-packages/pymysql/err.py", line 143, in raise_mysql_exception
    raise errorclass(errno, errval)
pymysql.err.OperationalError: (1045, "Access denied for user '_72158affdf1791ca'@'localhost' (using password: YES)")

mysqldump --single-transaction --quick --lock-tables=false -u _d7b2a4261c302107 -pC541lZ1J9x11RpHI _d7b2a4261c302107 -h 127.0.0.1 -P 3306   | /usr/bin/gzip >> ./projectmanagement.sys/private/backups/20211026_180002-projectmanagement_sys-database.sql.gz

Backup Summary for projectmanagement.sys at 2021-10-26 18:00:03.271705
Config  : ./projectmanagement.sys/private/backups/20211026_180002-projectmanagement_sys-site_config_backup.json 183.0B
Database: ./projectmanagement.sys/private/backups/20211026_180002-projectmanagement_sys-database.sql.gz         536.7KiB
Backup for Site projectmanagement.sys has been successfully completed
Backup failed for Site projectmanagement.system. Database or site_config.json may be corrupted
Traceback (most recent call last):
  File "/home/user/assignment/apps/frappe/frappe/commands/site.py", line 429, in backup
    odb = scheduled_backup(
  File "/home/user/assignment/apps/frappe/frappe/utils/backups.py", line 515, in scheduled_backup
    odb = new_backup(
  File "/home/user/assignment/apps/frappe/frappe/utils/backups.py", line 549, in new_backup
    odb = BackupGenerator(
  File "/home/user/assignment/apps/frappe/frappe/utils/backups.py", line 85, in __init__
    self.setup_backup_tables()
  File "/home/user/assignment/apps/frappe/frappe/utils/backups.py", line 119, in setup_backup_tables
    existing_doctypes = set([x.name for x in frappe.get_all("DocType")])
  File "/home/user/assignment/apps/frappe/frappe/__init__.py", line 1460, in get_all
    return get_list(doctype, *args, **kwargs)
  File "/home/user/assignment/apps/frappe/frappe/__init__.py", line 1433, in get_list
    return frappe.model.db_query.DatabaseQuery(doctype).execute(*args, **kwargs)
  File "/home/user/assignment/apps/frappe/frappe/model/db_query.py", line 102, in execute
    self.columns = self.get_table_columns()
  File "/home/user/assignment/apps/frappe/frappe/model/db_query.py", line 339, in get_table_columns
    return get_table_columns(self.doctype)
  File "/home/user/assignment/apps/frappe/frappe/model/meta.py", line 49, in get_table_columns
    return frappe.db.get_table_columns(doctype)
  File "/home/user/assignment/apps/frappe/frappe/database/database.py", line 893, in get_table_columns
    columns = self.get_db_table_columns('tab' + doctype)
  File "/home/user/assignment/apps/frappe/frappe/database/database.py", line 881, in get_db_table_columns
    columns = [r[0] for r in self.sql('''
  File "/home/user/assignment/apps/frappe/frappe/database/database.py", line 122, in sql
    self.connect()
  File "/home/user/assignment/apps/frappe/frappe/database/database.py", line 74, in connect
    self._conn = self.get_connection()
  File "/home/user/assignment/apps/frappe/frappe/database/mariadb/database.py", line 73, in get_connection
    conn = pymysql.connect(
  File "/home/user/assignment/env/lib/python3.8/site-packages/pymysql/connections.py", line 353, in __init__
    self.connect()
  File "/home/user/assignment/env/lib/python3.8/site-packages/pymysql/connections.py", line 633, in connect
    self._request_authentication()
  File "/home/user/assignment/env/lib/python3.8/site-packages/pymysql/connections.py", line 907, in _request_authentication
    auth_packet = self._read_packet()
  File "/home/user/assignment/env/lib/python3.8/site-packages/pymysql/connections.py", line 725, in _read_packet
    packet.raise_for_error()
  File "/home/user/assignment/env/lib/python3.8/site-packages/pymysql/protocol.py", line 221, in raise_for_error
    err.raise_mysql_exception(self._data)
  File "/home/user/assignment/env/lib/python3.8/site-packages/pymysql/err.py", line 143, in raise_mysql_exception
    raise errorclass(errno, errval)
pymysql.err.OperationalError: (1045, "Access denied for user '_72158affdf1791ca'@'localhost' (using password: YES)")

mysqldump --single-transaction --quick --lock-tables=false -u _d7b2a4261c302107 -pC541lZ1J9x11RpHI _d7b2a4261c302107 -h 127.0.0.1 -P 3306   | /usr/bin/gzip >> ./projectmanagement.sys/private/backups/20211027_120002-projectmanagement_sys-database.sql.gz

Backup Summary for projectmanagement.sys at 2021-10-27 12:00:04.331024
Config  : ./projectmanagement.sys/private/backups/20211027_120002-projectmanagement_sys-site_config_backup.json 183.0B
Database: ./projectmanagement.sys/private/backups/20211027_120002-projectmanagement_sys-database.sql.gz         539.9KiB
Backup for Site projectmanagement.sys has been successfully completed
Backup failed for Site projectmanagement.system. Database or site_config.json may be corrupted
Traceback (most recent call last):
  File "/home/user/assignment/apps/frappe/frappe/commands/site.py", line 429, in backup
    odb = scheduled_backup(
  File "/home/user/assignment/apps/frappe/frappe/utils/backups.py", line 515, in scheduled_backup
    odb = new_backup(
  File "/home/user/assignment/apps/frappe/frappe/utils/backups.py", line 549, in new_backup
    odb = BackupGenerator(
  File "/home/user/assignment/apps/frappe/frappe/utils/backups.py", line 85, in __init__
    self.setup_backup_tables()
  File "/home/user/assignment/apps/frappe/frappe/utils/backups.py", line 119, in setup_backup_tables
    existing_doctypes = set([x.name for x in frappe.get_all("DocType")])
  File "/home/user/assignment/apps/frappe/frappe/__init__.py", line 1460, in get_all
    return get_list(doctype, *args, **kwargs)
  File "/home/user/assignment/apps/frappe/frappe/__init__.py", line 1433, in get_list
    return frappe.model.db_query.DatabaseQuery(doctype).execute(*args, **kwargs)
  File "/home/user/assignment/apps/frappe/frappe/model/db_query.py", line 102, in execute
    self.columns = self.get_table_columns()
  File "/home/user/assignment/apps/frappe/frappe/model/db_query.py", line 339, in get_table_columns
    return get_table_columns(self.doctype)
  File "/home/user/assignment/apps/frappe/frappe/model/meta.py", line 49, in get_table_columns
    return frappe.db.get_table_columns(doctype)
  File "/home/user/assignment/apps/frappe/frappe/database/database.py", line 893, in get_table_columns
    columns = self.get_db_table_columns('tab' + doctype)
  File "/home/user/assignment/apps/frappe/frappe/database/database.py", line 881, in get_db_table_columns
    columns = [r[0] for r in self.sql('''
  File "/home/user/assignment/apps/frappe/frappe/database/database.py", line 122, in sql
    self.connect()
  File "/home/user/assignment/apps/frappe/frappe/database/database.py", line 74, in connect
    self._conn = self.get_connection()
  File "/home/user/assignment/apps/frappe/frappe/database/mariadb/database.py", line 73, in get_connection
    conn = pymysql.connect(
  File "/home/user/assignment/env/lib/python3.8/site-packages/pymysql/connections.py", line 353, in __init__
    self.connect()
  File "/home/user/assignment/env/lib/python3.8/site-packages/pymysql/connections.py", line 633, in connect
    self._request_authentication()
  File "/home/user/assignment/env/lib/python3.8/site-packages/pymysql/connections.py", line 907, in _request_authentication
    auth_packet = self._read_packet()
  File "/home/user/assignment/env/lib/python3.8/site-packages/pymysql/connections.py", line 725, in _read_packet
    packet.raise_for_error()
  File "/home/user/assignment/env/lib/python3.8/site-packages/pymysql/protocol.py", line 221, in raise_for_error
    err.raise_mysql_exception(self._data)
  File "/home/user/assignment/env/lib/python3.8/site-packages/pymysql/err.py", line 143, in raise_mysql_exception
    raise errorclass(errno, errval)
pymysql.err.OperationalError: (1045, "Access denied for user '_72158affdf1791ca'@'localhost' (using password: YES)")

mysqldump --single-transaction --quick --lock-tables=false -u _d7b2a4261c302107 -pC541lZ1J9x11RpHI _d7b2a4261c302107 -h 127.0.0.1 -P 3306   | /usr/bin/gzip >> ./projectmanagement.sys/private/backups/20211027_180002-projectmanagement_sys-database.sql.gz

Backup Summary for projectmanagement.sys at 2021-10-27 18:00:03.808952
Config  : ./projectmanagement.sys/private/backups/20211027_180002-projectmanagement_sys-site_config_backup.json 183.0B
Database: ./projectmanagement.sys/private/backups/20211027_180002-projectmanagement_sys-database.sql.gz         539.9KiB
Backup for Site projectmanagement.sys has been successfully completed
Backup failed for Site projectmanagement.system. Database or site_config.json may be corrupted
Traceback (most recent call last):
  File "/home/user/assignment/apps/frappe/frappe/commands/site.py", line 429, in backup
    odb = scheduled_backup(
  File "/home/user/assignment/apps/frappe/frappe/utils/backups.py", line 515, in scheduled_backup
    odb = new_backup(
  File "/home/user/assignment/apps/frappe/frappe/utils/backups.py", line 549, in new_backup
    odb = BackupGenerator(
  File "/home/user/assignment/apps/frappe/frappe/utils/backups.py", line 85, in __init__
    self.setup_backup_tables()
  File "/home/user/assignment/apps/frappe/frappe/utils/backups.py", line 119, in setup_backup_tables
    existing_doctypes = set([x.name for x in frappe.get_all("DocType")])
  File "/home/user/assignment/apps/frappe/frappe/__init__.py", line 1460, in get_all
    return get_list(doctype, *args, **kwargs)
  File "/home/user/assignment/apps/frappe/frappe/__init__.py", line 1433, in get_list
    return frappe.model.db_query.DatabaseQuery(doctype).execute(*args, **kwargs)
  File "/home/user/assignment/apps/frappe/frappe/model/db_query.py", line 102, in execute
    self.columns = self.get_table_columns()
  File "/home/user/assignment/apps/frappe/frappe/model/db_query.py", line 339, in get_table_columns
    return get_table_columns(self.doctype)
  File "/home/user/assignment/apps/frappe/frappe/model/meta.py", line 49, in get_table_columns
    return frappe.db.get_table_columns(doctype)
  File "/home/user/assignment/apps/frappe/frappe/database/database.py", line 893, in get_table_columns
    columns = self.get_db_table_columns('tab' + doctype)
  File "/home/user/assignment/apps/frappe/frappe/database/database.py", line 881, in get_db_table_columns
    columns = [r[0] for r in self.sql('''
  File "/home/user/assignment/apps/frappe/frappe/database/database.py", line 122, in sql
    self.connect()
  File "/home/user/assignment/apps/frappe/frappe/database/database.py", line 74, in connect
    self._conn = self.get_connection()
  File "/home/user/assignment/apps/frappe/frappe/database/mariadb/database.py", line 73, in get_connection
    conn = pymysql.connect(
  File "/home/user/assignment/env/lib/python3.8/site-packages/pymysql/connections.py", line 353, in __init__
    self.connect()
  File "/home/user/assignment/env/lib/python3.8/site-packages/pymysql/connections.py", line 633, in connect
    self._request_authentication()
  File "/home/user/assignment/env/lib/python3.8/site-packages/pymysql/connections.py", line 907, in _request_authentication
    auth_packet = self._read_packet()
  File "/home/user/assignment/env/lib/python3.8/site-packages/pymysql/connections.py", line 725, in _read_packet
    packet.raise_for_error()
  File "/home/user/assignment/env/lib/python3.8/site-packages/pymysql/protocol.py", line 221, in raise_for_error
    err.raise_mysql_exception(self._data)
  File "/home/user/assignment/env/lib/python3.8/site-packages/pymysql/err.py", line 143, in raise_mysql_exception
    raise errorclass(errno, errval)
pymysql.err.OperationalError: (1045, "Access denied for user '_72158affdf1791ca'@'localhost' (using password: YES)")

mysqldump --single-transaction --quick --lock-tables=false -u _d7b2a4261c302107 -pC541lZ1J9x11RpHI _d7b2a4261c302107 -h 127.0.0.1 -P 3306   | /usr/bin/gzip >> ./projectmanagement.sys/private/backups/20211028_120002-projectmanagement_sys-database.sql.gz

Backup Summary for projectmanagement.sys at 2021-10-28 12:00:03.896113
Config  : ./projectmanagement.sys/private/backups/20211028_120002-projectmanagement_sys-site_config_backup.json 183.0B
Database: ./projectmanagement.sys/private/backups/20211028_120002-projectmanagement_sys-database.sql.gz         541.6KiB
Backup for Site projectmanagement.sys has been successfully completed
Backup failed for Site projectmanagement.system. Database or site_config.json may be corrupted
Traceback (most recent call last):
  File "/home/user/assignment/apps/frappe/frappe/commands/site.py", line 429, in backup
    odb = scheduled_backup(
  File "/home/user/assignment/apps/frappe/frappe/utils/backups.py", line 515, in scheduled_backup
    odb = new_backup(
  File "/home/user/assignment/apps/frappe/frappe/utils/backups.py", line 549, in new_backup
    odb = BackupGenerator(
  File "/home/user/assignment/apps/frappe/frappe/utils/backups.py", line 85, in __init__
    self.setup_backup_tables()
  File "/home/user/assignment/apps/frappe/frappe/utils/backups.py", line 119, in setup_backup_tables
    existing_doctypes = set([x.name for x in frappe.get_all("DocType")])
  File "/home/user/assignment/apps/frappe/frappe/__init__.py", line 1460, in get_all
    return get_list(doctype, *args, **kwargs)
  File "/home/user/assignment/apps/frappe/frappe/__init__.py", line 1433, in get_list
    return frappe.model.db_query.DatabaseQuery(doctype).execute(*args, **kwargs)
  File "/home/user/assignment/apps/frappe/frappe/model/db_query.py", line 102, in execute
    self.columns = self.get_table_columns()
  File "/home/user/assignment/apps/frappe/frappe/model/db_query.py", line 339, in get_table_columns
    return get_table_columns(self.doctype)
  File "/home/user/assignment/apps/frappe/frappe/model/meta.py", line 49, in get_table_columns
    return frappe.db.get_table_columns(doctype)
  File "/home/user/assignment/apps/frappe/frappe/database/database.py", line 893, in get_table_columns
    columns = self.get_db_table_columns('tab' + doctype)
  File "/home/user/assignment/apps/frappe/frappe/database/database.py", line 881, in get_db_table_columns
    columns = [r[0] for r in self.sql('''
  File "/home/user/assignment/apps/frappe/frappe/database/database.py", line 122, in sql
    self.connect()
  File "/home/user/assignment/apps/frappe/frappe/database/database.py", line 74, in connect
    self._conn = self.get_connection()
  File "/home/user/assignment/apps/frappe/frappe/database/mariadb/database.py", line 73, in get_connection
    conn = pymysql.connect(
  File "/home/user/assignment/env/lib/python3.8/site-packages/pymysql/connections.py", line 353, in __init__
    self.connect()
  File "/home/user/assignment/env/lib/python3.8/site-packages/pymysql/connections.py", line 633, in connect
    self._request_authentication()
  File "/home/user/assignment/env/lib/python3.8/site-packages/pymysql/connections.py", line 907, in _request_authentication
    auth_packet = self._read_packet()
  File "/home/user/assignment/env/lib/python3.8/site-packages/pymysql/connections.py", line 725, in _read_packet
    packet.raise_for_error()
  File "/home/user/assignment/env/lib/python3.8/site-packages/pymysql/protocol.py", line 221, in raise_for_error
    err.raise_mysql_exception(self._data)
  File "/home/user/assignment/env/lib/python3.8/site-packages/pymysql/err.py", line 143, in raise_mysql_exception
    raise errorclass(errno, errval)
pymysql.err.OperationalError: (1045, "Access denied for user '_72158affdf1791ca'@'localhost' (using password: YES)")

